Workbook

Sheet Base_de_dados
A1: id_do_anuncio | B1: data | C1: campanha | D1: faixa_etaria | E1: genero | F1: qte_de_exibições_do_anuncio | G1: qte_de_clicks | H1: valor_investido_no_anúncio | I1: qte_de_vendas | J1: ROI
A2: Ad_01 | B2: 44562 | C2: Campanha A | D2: 30-34 | E2: F | F2: 57665 | G2: 700 | H2: 18070 | I2: 100 | J2: =Análises!F2 -> 0.66021032
A3: Ad_01 | B3: 44563 | C3: Campanha A | D3: 30-34 | E3: F | F3: 3091 | G3: 50 | H3: 1610 | I3: 100 | J3: =Análises!F3 -> 17.63354
A4: Ad_01 | B4: 44564 | C4: Campanha A | D4: 30-34 | E4: F | F4: 5014 | G4: 50 | H4: 1190.0001 | I4: 50 | J4: =Análises!F4 -> 11.605041
A5: Ad_01 | B5: 44565 | C5: Campanha A | D5: 30-34 | E5: F | F5: 38726 | G5: 350 | H5: 9220.0003 | I5: 50 | J5: =Análises!F5 -> 0.626898
A6: Ad_01 | B6: 44566 | C6: Campanha A | D6: 30-34 | E6: F | F6: 5369 | G6: 50 | H6: 1510 | I6: 50 | J6: =Análises!F6 -> 8.9337749
A7: Ad_01 | B7: 44567 | C7: Campanha A | D7: 30-34 | E7: F | F7: 22221 | G7: 350 | H7: 9430.0001 | I7: 100 | J7: =Análises!F7 -> 2.1813361
A8: Ad_01 | B8: 44568 | C8: Campanha A | D8: 30-34 | E8: F | F8: 13019 | G8: 250 | H8: 6960 | I8: 50 | J8: =Análises!F8 -> 1.1551724
A9: Ad_02 | B9: 44569 | C9: Campanha A | D9: 30-34 | E9: M | F9: 7350 | G9: 50 | H9: 1429.9999 | I9: 150 | J9: =Análises!F9 -> 30.468533
A10: Ad_02 | B10: 44570 | C10: Campanha A | D10: 30-34 | E10: M | F10: 17861 | G10: 100 | H10: 1820 | I10: 100 | J10: =Análises!F10 -> 15.483516
A11: Ad_02 | B11: 44571 | C11: Campanha A | D11: 30-34 | E11: M | F11: 4259 | G11: 50 | H11: 1250 | I11: 50 | J11: =Análises!F11 -> 11
A12: Ad_02 | B12: 44572 | C12: Campanha A | D12: 30-34 | E12: M | F12: 4133 | G12: 50 | H12: 1290 | I12: 100 | J12: =Análises!F12 -> 22.255815
A13: Ad_02 | B13: 44573 | C13: Campanha A | D13: 30-34 | E13: M | F13: 15615 | G13: 150 | H13: 4770 | I13: 50 | J13: =Análises!F13 -> 2.1446541
... A937: Ad_24 | B937: 44766 | C937: Campanha C | D937: 45-49 | E937: M | F937: 150858 | G937: 1050 | H937: 30260 | I937: 400 | J937: =Análises!F937 -> 2.9656312

Sheet Análises
A1: ID_Anuncio | B1: CTR | C1: CPC | D1: Receita | E1: CAC | F1: ROI | H1: IDADE | I1: Media ROI
A2: =Base_de_dados!A2 -> Ad_01 | B2: =Base_de_dados!G2/Base_de_dados!F2 -> 0.012139079 | C2: =Base_de_dados!G2/Base_de_dados!H2 -> 0.038738241 | D2: =Base_de_dados!I2*300 -> 30000 | E2: =Base_de_dados!H2/Base_de_dados!I2 -> 180.7 | F2: =(D2-Base_de_dados!H2)/Base_de_dados!H2 -> 0.66021032 | H2: =Check_duplicidade_faixa_etaria!A2 -> 30-34 | I2: =Check_duplicidade_faixa_etaria!B2 -> 10.108209
A3: =Base_de_dados!A3 -> Ad_01 | B3: =Base_de_dados!G3/Base_de_dados!F3 -> 0.016175995 | C3: =Base_de_dados!G3/Base_de_dados!H3 -> 0.0310559 | D3: =Base_de_dados!I3*300 -> 30000 | E3: =Base_de_dados!H3/Base_de_dados!I3 -> 16.1 | F3: =(D3-Base_de_dados!H3)/Base_de_dados!H3 -> 17.63354 | H3: =Check_duplicidade_faixa_etaria!A3 -> 35-39 | I3: =Check_duplicidade_faixa_etaria!B3 -> 7.0856423
A4: =Base_de_dados!A4 -> Ad_01 | B4: =Base_de_dados!G4/Base_de_dados!F4 -> 0.0099720782 | C4: =Base_de_dados!G4/Base_de_dados!H4 -> 0.042016805 | D4: =Base_de_dados!I4*300 -> 15000 | E4: =Base_de_dados!H4/Base_de_dados!I4 -> 23.800001 | F4: =(D4-Base_de_dados!H4)/Base_de_dados!H4 -> 11.605041 | H4: =Check_duplicidade_faixa_etaria!A4 -> 40-44 | I4: =Check_duplicidade_faixa_etaria!B4 -> 4.7885586
A5: =Base_de_dados!A5 -> Ad_01 | B5: =Base_de_dados!G5/Base_de_dados!F5 -> 0.0090378557 | C5: =Base_de_dados!G5/Base_de_dados!H5 -> 0.037960953 | D5: =Base_de_dados!I5*300 -> 15000 | E5: =Base_de_dados!H5/Base_de_dados!I5 -> 184.40001 | F5: =(D5-Base_de_dados!H5)/Base_de_dados!H5 -> 0.626898 | H5: =Check_duplicidade_faixa_etaria!A5 -> 45-49 | I5: =Check_duplicidade_faixa_etaria!B5 -> 3.9843608
A6: =Base_de_dados!A6 -> Ad_01 | B6: =Base_de_dados!G6/Base_de_dados!F6 -> 0.0093127212 | C6: =Base_de_dados!G6/Base_de_dados!H6 -> 0.033112583 | D6: =Base_de_dados!I6*300 -> 15000 | E6: =Base_de_dados!H6/Base_de_dados!I6 -> 30.2 | F6: =(D6-Base_de_dados!H6)/Base_de_dados!H6 -> 8.9337749
A7: =Base_de_dados!A7 -> Ad_01 | B7: =Base_de_dados!G7/Base_de_dados!F7 -> 0.015750866 | C7: =Base_de_dados!G7/Base_de_dados!H7 -> 0.037115588 | D7: =Base_de_dados!I7*300 -> 30000 | E7: =Base_de_dados!H7/Base_de_dados!I7 -> 94.300001 | F7: =(D7-Base_de_dados!H7)/Base_de_dados!H7 -> 2.1813361
A8: =Base_de_dados!A8 -> Ad_01 | B8: =Base_de_dados!G8/Base_de_dados!F8 -> 0.019202704 | C8: =Base_de_dados!G8/Base_de_dados!H8 -> 0.03591954 | D8: =Base_de_dados!I8*300 -> 15000 | E8: =Base_de_dados!H8/Base_de_dados!I8 -> 139.2 | F8: =(D8-Base_de_dados!H8)/Base_de_dados!H8 -> 1.1551724
A9: =Base_de_dados!A9 -> Ad_02 | B9: =Base_de_dados!G9/Base_de_dados!F9 -> 0.0068027211 | C9: =Base_de_dados!G9/Base_de_dados!H9 -> 0.034965036 | D9: =Base_de_dados!I9*300 -> 45000 | E9: =Base_de_dados!H9/Base_de_dados!I9 -> 9.533333 | F9: =(D9-Base_de_dados!H9)/Base_de_dados!H9 -> 30.468533
A10: =Base_de_dados!A10 -> Ad_02 | B10: =Base_de_dados!G10/Base_de_dados!F10 -> 0.0055987907 | C10: =Base_de_dados!G10/Base_de_dados!H10 -> 0.054945054 | D10: =Base_de_dados!I10*300 -> 30000 | E10: =Base_de_dados!H10/Base_de_dados!I10 -> 18.2 | F10: =(D10-Base_de_dados!H10)/Base_de_dados!H10 -> 15.483516
A11: =Base_de_dados!A11 -> Ad_02 | B11: =Base_de_dados!G11/Base_de_dados!F11 -> 0.011739845 | C11: =Base_de_dados!G11/Base_de_dados!H11 -> 0.04 | D11: =Base_de_dados!I11*300 -> 15000 | E11: =Base_de_dados!H11/Base_de_dados!I11 -> 25 | F11: =(D11-Base_de_dados!H11)/Base_de_dados!H11 -> 11
A12: =Base_de_dados!A12 -> Ad_02 | B12: =Base_de_dados!G12/Base_de_dados!F12 -> 0.01209775 | C12: =Base_de_dados!G12/Base_de_dados!H12 -> 0.038759691 | D12: =Base_de_dados!I12*300 -> 30000 | E12: =Base_de_dados!H12/Base_de_dados!I12 -> 12.9 | F12: =(D12-Base_de_dados!H12)/Base_de_dados!H12 -> 22.255815
A13: =Base_de_dados!A13 -> Ad_02 | B13: =Base_de_dados!G13/Base_de_dados!F13 -> 0.0096061479 | C13: =Base_de_dados!G13/Base_de_dados!H13 -> 0.031446541 | D13: =Base_de_dados!I13*300 -> 15000 | E13: =Base_de_dados!H13/Base_de_dados!I13 -> 95.4 | F13: =(D13-Base_de_dados!H13)/Base_de_dados!H13 -> 2.1446541
A14: =Base_de_dados!A14 -> Ad_02 | B14: =Base_de_dados!G14/Base_de_dados!F14 -> 0.0045657931 | C14: =Base_de_dados!G14/Base_de_dados!H14 -> 0.039370079 | D14: =Base_de_dados!I14*300 -> 30000 | E14: =Base_de_dados!H14/Base_de_dados!I14 -> 12.7 | F14: =(D14-Base_de_dados!H14)/Base_de_dados!H14 -> 22.622048
A15: =Base_de_dados!A15 -> Ad_02 | B15: =Base_de_dados!G15/Base_de_dados!F15 -> 0.021231423 | C15: =Base_de_dados!G15/Base_de_dados!H15 -> 0.033333333 | D15: =Base_de_dados!I15*300 -> 15000 | E15: =Base_de_dados!H15/Base_de_dados!I15 -> 30 | F15: =(D15-Base_de_dados!H15)/Base_de_dados!H15 -> 9
A16: =Base_de_dados!A16 -> Ad_02 | B16: =Base_de_dados!G16/Base_de_dados!F16 -> 0.01578615 | C16: =Base_de_dados!G16/Base_de_dados!H16 -> 0.047468355 | D16: =Base_de_dados!I16*300 -> 15000 | E16: =Base_de_dados!H16/Base_de_dados!I16 -> 63.199999 | F16: =(D16-Base_de_dados!H16)/Base_de_dados!H16 -> 3.7468355
A17: =Base_de_dados!A17 -> Ad_02 | B17: =Base_de_dados!G17/Base_de_dados!F17 -> 0.02385984 | C17: =Base_de_dados!G17/Base_de_dados!H17 -> 0.034046692 | D17: =Base_de_dados!I17*300 -> 30000 | E17: =Base_de_dados!H17/Base_de_dados!I17 -> 102.8 | F17: =(D17-Base_de_dados!H17)/Base_de_dados!H17 -> 1.9182879
... A937: =Base_de_dados!A937 -> Ad_24 | B937: =Base_de_dados!G937/Base_de_dados!F937 -> 0.0069601877 | C937: =Base_de_dados!G937/Base_de_dados!H937 -> 0.034699273 | D937: =Base_de_dados!I937*300 -> 120000 | E937: =Base_de_dados!H937/Base_de_dados!I937 -> 75.65 | F937: =(D937-Base_de_dados!H937)/Base_de_dados!H937 -> 2.9656312

Sheet Check_duplicidade_faixa_etaria
A1: Idade | B1: ROI Médio
A2: 30-34 | B2: =AVERAGEIF(Base_de_dados!$D$2:$D$937,"30-34",Análises!$F$2:$F$937) -> 10.108209
A3: 35-39 | B3: =AVERAGEIF(Base_de_dados!$D$2:$D$937,"35-39",Análises!$F$2:$F$937) -> 7.0856423
A4: 40-44 | B4: =AVERAGEIF(Base_de_dados!$D$2:$D$937,"40-44",Análises!$F$2:$F$937) -> 4.7885586
A5: 45-49 | B5: =AVERAGEIF(Base_de_dados!$D$2:$D$937,"45-49",Análises!$F$2:$F$937) -> 3.9843608

Sheet depara_categoria
A1: categoria_de_interesse | B1: descrição_da_categoria
A2: 2 | B2: Business and Industry
A3: 7
A4: 10
A5: 15
A6: 16 | B6: Entertainment
A7: 18
A8: 19
A9: 20
A10: 21 | B10: Family and relationships
A11: 22
A12: 23
A13: 24
A14: 25 | B14: Fitness and wellness
A15: 26
A16: 27
A17: 28
A18: 29 | B18: Food and drink
A19: 30
A20: 31
A21: 32
A22: 36 | B22: Hobbies and activities
A23: 63
A24: 64
A25: 65
A26: 66 | B26: Shopping and fashion
A27: 100
A28: 101
A29: 102
A30: 103 | B30: Sports and outdoors
A31: 104
A32: 105
A33: 106
A34: 107 | B34: Technology
A35: 108
A36: 109
A37: 110
A38: 111
A39: 112
A40: 113
...

Sheet Planilha8
A1: Business and Industry
A3: Advertising Agriculture Architecture Aviation Banking
A5: Investment banking Online banking Retail banking
A7: Business Construction Design
A9: Fashion design Graphic design Interior design
A11: Economics Engineering Entrepreneurship Health care Higher education Management Marketing Nursing
A13: Online
A14: Digital marketing
A16: Display advertising
A17: Email marketing
A18: Online advertising
A19: Search engine optimization Social media
... A232: Mobile phones Portable media players Projectors Smartphones Televisions
